Workbook

Sheet Leyenda
A1: Revisión de los errores de 1920 contra el Libro de Mormón de 1946
A3: Hoja "Errores": una fila por cada error registrado en "errors in 1920.txt", en el orden del libro (preliminares, 1 Nefi ... Moroni). Las entradas FAMILIA se desglosan en sus instancias (columna Familia).
A4: Columnas que usted llena (fondo amarillo):
A5: P 1946: ¿qué dice? -- lista: igual que 1920 / corregido / otro cambio / no encontrado / no se puede leer
A6: Q 1946: lectura / nota -- lo que imprime 1946, si difiere, o cualquier observación
A7: R Decisión Gutenberg 1920 (_cleaned) -- lista: corregir / mantener / pendiente / ver comentario
A8: S Decisión versión moderna -- lista: modernizar / mantener / pendiente / ver comentario
A9: T Comentarios -- texto libre
A10: Las listas son una ayuda: puede escribir otra cosa en cualquier celda amarilla.
A12: Ejemplo de una fila llenada (formato esperado):
A13: Alma 36:20 | Lectura 1920: "Biblía" | 1946: corregido | Lectura/nota: "Biblia" | Gutenberg: corregir | Moderna: modernizar | Comentarios: 1946 lo corrige
A15: Columna N "Aviso": "instancia extraída ... verificar" = fila generada a partir del texto de una FAMILIA; puede ser una cita de comparación y no un error -- basta con marcarla "no encontrado" o anotarlo. "ubicación aproximada" = la entrada no tiene referencia exacta.
... A19: Avance
A20: Filas en total | B20: =COUNTA(Errores!A2:A2187)
A21: Filas con lectura de 1946 | B21: =COUNTA(Errores!P2:P2187)
A22: de ellas "corregido" | B22: =COUNTIF(Errores!P2:P2187,"corregido")
A23: de ellas "igual que 1920" | B23: =COUNTIF(Errores!P2:P2187,"igual que 1920")
A24: Filas con decisión Gutenberg | B24: =COUNTA(Errores!R2:R2187)
A25: Filas con decisión moderna | B25: =COUNTA(Errores!S2:S2187)
A27: Hoja "Familias", columnas D-F (añadidas 2026-10-18):
A28: D versículos sugeridos (unos 5 repartidos por el libro) para mirar en 1946
A29: E resultado: corrige todos / mantiene todos / mixto / no encontrado
A30: F nota libre. Si las 5 coinciden, no hace falta mirar las demás filas de esa familia en "Errores".

Sheet Errores
A1: # | B1: Libro | C1: Cap. | D1: Vers. | E1: Pág. 1920 | F1: Lugar | G1: Nota (n.º / clave) | H1: Lectura 1920 | I1: Forma correcta | J1: Tipo | K1: 1886 (según el registro) | L1: Familia | M1: Propuesta _cleaned ya registrada | N1: Aviso | O1: Línea en el registro | P1: 1946: ¿qué dice? | Q1: 1946: lectura / nota | R1: Decisión Gutenberg 1920 (_cleaned) | S1: Decisión versión moderna | T1: Comentarios | U1: Entrada completa del registro
A2: 1 | B2: Preliminares | E2: iii | F2: portada | H2: revalación | I2: revelación | J2: letra(s) | K2: es correcto en la de 1886 | O2: 2 | P2: corregido | R2: corregir | U2: Página del título iii revalación (revelación) (es correcto en la de 1886)
A3: 2 | B3: Preliminares | E3: iii | F3: portada | H3: Ultimos | I3: Últimos | J3: tilde | K3: transcripción ya coincide con la impresión; 1886 no cotejado | O3: 3 | P3: corregido | R3: corregir | U3: Página del título iii Ultimos (Últimos) (1920 imprime "Santos de los Ultimos Días" sin tilde en la "U" mayúscula, aunque la misma línea acentúa "Días" y la fuente tiene mayúsculas acentuadas; pages_1920/page_0011.png; confirmado en la imagen 2026-10-17 (revisión de variantes de tilde, item 4a); la transcripción ya coincide con la impresión; 1886 no cotejado)
A4: 3 | B4: Preliminares | E4: v | F4: testimonios | H4: Nuestros Señor, Jesucristo | I4: Nuestro Señor, Jesu Cristo | J4: palabra(s)/gramática | K4: de Jesucristo 1886 | O4: 4 | P4: corregido | Q4: de nuestro Señor, Jesucristo | R4: corregir | U4: Testimonios página v Nuestros Señor, Jesucristo (Nuestro Señor, Jesu Cristo)(de Jesucristo 1886)
A5: 4 | B5: Preliminares | E5: v | F5: testimonios | H5: los grabado que | I5: los grabados que | J5: letra(s) | K5: 1886 dice los grabados | O5: 5 | P5: corregido | R5: corregir | U5: Testimonios página v los grabado que (los grabados que) (1886 dice los grabados)
A6: 5 | B6: Preliminares | E6: vii | F6: índice | H6: Sueño de Lahi | I6: Sueño de Lehi | J6: letra(s) | K6: Lehi en 1886 | O6: 6 | P6: no encontrado | Q6: No hay ese tipo de indice | R6: corregir | U6: Indice página vii Sueño de Lahi (Sueño de Lehi) (Lehi en 1886)
A7: 6 | B7: Preliminares | E7: vii | F7: índice | H7: bronze | I7: bronce | J7: letra(s) | K7: bronze en 1886 | O7: 7 | P7: no encontrado | R7: ver comentario | T7: Research usage of bronze | U7: Indice página vii bronze (bronce) 2x (bronze en 1886)
A8: 7 | B8: Preliminares | E8: vii | F8: índice | H8: atras | I8: atrás | J8: tilde | K8: coincide con la impresión; atras también en 1886 | O8: 16 | P8: no encontrado | R8: corregir | U8: Indice página vii atras (atrás) ("el barco es arrojado hacia atras.. 45"; pages_1920/page_0015.png; confirmado en la imagen 2026-10-17 (revisión de variantes de tilde, item 4a); la transcripción ya coincide con la impresión; atras también en 1886)
A9: 8 | B9: Preliminares | E9: viii | F9: índice | H9: Baustismo | I9: Bautismo | J9: letra(s) | K9: Bautismo en 1886 | O9: 8 | P9: no encontrado | R9: corregir | U9: Indice página viii Baustismo (Bautismo) (Bautismo en 1886)
A10: 9 | B10: Preliminares | E10: viii | F10: índice | H10: sobrepajado | I10: sobrepujado | J10: letra(s) | K10: Sobrepujado en 1886 | O10: 9 | P10: no encontrado | R10: corregir | U10: Indice página viii sobrepajado (sobrepujado) (Sobrepujado en 1886)
A11: 10 | B11: Preliminares | E11: viii | F11: índice | H11: Isaias | I11: Isaías | J11: tilde | K11: ción ya coincide con la impresión; Isaías en 1886 | O11: 17 | P11: no encontrado | R11: corregir | U11: Indice página viii Isaias (Isaías) ("Palabras de Isaias (por Jacob).. 75"; pages_1920/page_0016.png; confirmado en la imagen 2026-10-17 (revisión de variantes de tilde, item 4a); la transcripción ya coincide con la impresión; Isaías en 1886)
A12: 11 | B12: Preliminares | E12: viii | F12: índice | H12: Moises | I12: Moisés | J12: tilde | K12: ción ya coincide con la impresión; Moisés en 1886 | O12: 18 | P12: no encontrado | R12: corregir | U12: Indice página viii Moises (Moisés) ("Guardan la ley de Moises.. 111"; pages_1920/page_0016.png; confirmado en la imagen 2026-10-17 (revisión de variantes de tilde, item 4a); la transcripción ya coincide con la impresión; Moisés en 1886)
A13: 12 | B13: Preliminares | E13: ix | F13: índice | H13: prisón | I13: prisión | J13: letra(s) | K13: prision -- no accento en 1886 - intention was to add accent? | O13: 10 | P13: no encontrado | R13: corregir | U13: Indice página ix prisón (prisión) (prision -- no accento en 1886 - intention was to add accent?)
A14: 13 | B14: Preliminares | E14: ix | F14: índice | H14: Lamaitas | I14: Lamanitas | J14: letra(s) | K14: 1886 aún no cotejado para este lugar exacto | O14: 13 | P14: no encontrado | R14: corregir | U14: Indice página ix Lamaitas (Lamanitas) ("Sueño profundo de los Lama-itas.. 218-219" -- falta la "n" justo después del guión de partición de línea "Lama-"; confirmado independientemente en la imagen de 1920 (pages_1920/page_0017.png, zoom) y en la capa de OCR incrustada del propio PDF (que también lee "Lama-" / "itas" sin "n"); segunda aparición del mismo tipo de error que la ya registrada en "Indice página xii Lamaitas" (entrada distinta, página distinta); 1886 aún no cotejado para este lugar exacto; hallado 2026-09-11 durante la revisión del índice -- véase `workspace/diff1920ocr-trans.md`; preservado como se imprime en librodm_transcribed)
A15: 14 | B15: Preliminares | E15: ix | F15: índice | H15: Elderes | I15: Élderes | J15: tilde | K15: oincide con la impresión; Elderes también en 1886 | O15: 19 | P15: no encontrado | R15: corregir | U15: Indice página ix Elderes (Élderes) ("Alma ordena Sacerdotes y Elderes 253"; pages_1920/page_0017.png; confirmado en la imagen 2026-10-17 (revisión de variantes de tilde, item 4a); la transcripción ya coincide con la impresión; Elderes también en 1886; el cuerpo escribe "Élderes" 5 veces)
A16: 15 | B16: Preliminares | E16: x | F16: índice | H16: Restrauración | I16: Restauración | J16: letra(s) | K16: Restauración en 1886 | O16: 11 | P16: no encontrado | R16: corregir | U16: Indice página x Restrauración (Restauración) (Restauración en 1886) (corregida la cita de página 2026-09-11: estaba etiquetada "página ix" por error -- la entrada "Restrauración .. 358" cae en el bloque de librodm.txt bajo el marcador "Página x", no "ix"; confirmado contra la imagen de 1920, pages_1920/page_0018.png)
A17: 16 | B17: Preliminares | E17: x | F17: índice | H17: Zarahemnah | I17: Zerahémnah | J17: letra(s) | K17: frente al cuerpo, no un error de paginación; 1886 aún no cotejado para este lugar exacto | O17: 12 | P17: no encontrado | R17: corregir | U17: Indice página x Zarahemnah (Zerahémnah) ("Discurso de Moroni á Zarahemnah.. 369", entrada del índice de Alma capítulo 44; confirmado contra la imagen de 1920, pages_1920/page_0018.png; el CUERPO del texto (Alma 43-44, en torno a la pág. 369-370) escribe el nombre de este capitán lamanita SIEMPRE "Zerahémnah" -- 17 apariciones, todas idénticas, `grep -c` -- nunca "Zarahemnah"; el índice es la única discrepancia; la referencia de página en sí es correcta -- el discurso de Moroni sí ocurre en la pág. 369 -- se trata de una variante de grafía del índice frente al cuerpo, no un error de paginación; 1886 aún no cotejado para este lugar exacto; hallado 2026-09-11 durante la extensión del cotejo del índice a las 474 entradas -- véase `workspace/diff1920ocr-trans.md`; preservado como se imprime en librodm_transcribed)
A18: 17 | B18: Preliminares | E18: x | F18: índice | H18: jovenes | I18: jóvenes | J18: tilde | K18: ión ya coincide con la impresión; jóvenes en 1886 | O18: 20 | P18: no encontrado | R18: corregir | U18: Indice página x jovenes (jóvenes) ("Los 2000 jovenes hijos de los Ammonitas 400-401"; pages_1920/page_0018.png; confirmado en la imagen 2026-10-17 (revisión de variantes de tilde, item 4a); la transcripción ya coincide con la impresión; jóvenes en 1886)
A19: 18 | B19: Preliminares | E19: xi | F19: índice | H19: Espiritu | I19: Espíritu | J19: tilde | K19: ón ya coincide con la impresión; Espíritu en 1886 | O19: 21 | P19: no encontrado | R19: corregir | U19: Indice página xi Espiritu (Espíritu) ("Nefi llevado por el Espiritu.. 463"; pages_1920/page_0019.png; confirmado en la imagen 2026-10-17 (revisión de variantes de tilde, item 4a); la transcripción ya coincide con la impresión; Espíritu en 1886)
... A21: 20 | B21: Preliminares | E21: xiii | F21: índice | H21: granancia | I21: ganancia | J21: letra(s) | K21: ganancia en 1886 | O21: 15 | P21: no encontrado | R21: corregir | U21: Indice página xiii granancia (ganancia) (ganancia en 1886)
A22: 21 | B22: 1 Nefi | C22: 1 | D22: 2 | E22: 1 | F22: texto | H22: lenguage | I22: lenguaje | J22: familia | K22: pág. 466/467, LIBRO DE HELAMÁN CAPÍTULO 11; 1886 comparte "pillage" en este lugar exacto, pages_18 | L22: -age | M22: -> _cleaned (DECISIÓN DEL EDITOR | O22: 22 | U22: FAMILIA -age (por -aje) -- grafía "-age" arcaica donde el español moderno escribe "-aje". ENTRADA MAESTRA (2026-09-09; consolida las entradas antes dispersas de 1 Nefi 1:2 y 1 Nefi 5:3, ambas "el/este lenguage"). Alcance: "lenguage" 11 apariciones en el cuerpo (`grep -nE "lenguage" librodm_transcribed.txt`) + "lenguage del libro" en el índice (pág. xiii) + "344 días de pasage" en el índice (pág. xiii, entrada de Éther 6:11) + "pillage" 1x en el cuerpo (Helamán 11:25, "Y entregándose al pillage y al asesinato", pág. 466/467, LIBRO DE HELAMÁN CAPÍTULO 11; 1886 comparte "pillage" en este lugar exacto, pages_1886/page_0481.png, book page 463/file 481). Frente a "lenguaje" 3x, "pasaje" 12x y "pillaje/pillajes" 13x en el cuerpo (Helamán 11:25 es la ÚNICA aparición de "pillage" -- 1920 usa "pillaje" en las otras 13). La grafía "-age" (mensage/linage/viage/salvage/lenguage/pasage) fue la NORMA del español hasta que la RAE estandarizó "-aje" (~1815); para 1886/1920 era arcaica pero aún frecuente en imprenta. 1920 ya ha completado el cambio a "-aje" en TODAS las demás palabras (mensaje 22x, viaje 29x, salvaje 5x, linaje 4x, ultraje 2x -- 0 con "-age"), quedando SOLO "lenguage" (su forma de casa dominante, 11:3) y un "pasage" suelto en el índice. 1886: comparte "lenguage" ("lenguage en 1886" en las entradas originales de 1 Nefi 1:2 y 5:3). Atestiguación externa: "-age" en estas palabras = 0 en Quijote / Reina-Valera 1909 NT / Reina-Valera Biblia completa; "lenguaje" Quijote 10, "pasaje" Quijote 10, "pillaje" 1 en Reina-Valera Biblia completa (0 "pillage"). CLASIFICACIÓN: grafía ortográfica arcaica de época (norma pre-1815), compartida con 1886, NO un error tipográfico; edición inconsistente (casi todo "-aje", pero "lenguage" mayoritario). -> _cleaned (DECISIÓN DEL EDITOR): normalizar las apariciones restantes de "-age" a "-aje" (lenguage -> lenguaje; pasage -> pasaje; pillage -> pillaje, forma ya mayoritaria 13:1 en la propia 1920), como regularización de una grafía de época, no como corrección de errores. Preservado como se imprime en librodm_transcribed.
A23: 22 | B23: 1 Nefi | C23: 1 | D23: 9 | E23: 2 | F23: texto | H23: su resplendor era | I23: su resplandor era | J23: letra(s) | K23: resplendor en 1886 | O23: 29 | U23: 1 Nefi 1:9 su resplendor era (su resplandor era) (resplendor en 1886)
A24: 23 | B24: 1 Nefi | C24: 1 | D24: 9 | E24: 2 | F24: texto | H24: ("él" por "el") | I24: (ver la entrada de la familia) | J24: familia | K24: . 1886: el texto OCR del PDF de 1886 | L24: "él" por "el" | M24: _cleaned`, normalizar a "el" sin tilde | N24: forma no hallada en este versículo: quizá cita de comparación, no error -- verificar | O24: 85 | U24: FAMILIA "él" por "el" (artículo acentuado como pronombre ante "de"/"que") -- ENTRADA MAESTRA (2026-09-23, abierta durante el `manual-proofread` de Alma 43; consolida las entradas antes sueltas de Alma 40:6, Mormón 6:21 y Éther 12:38). 1920 imprime sistemáticamente con tilde el ARTÍCULO "el" cuando va ante "de"/"del" (sustantivo elidido: "mayor que él de los Nefitas" = "mayor que el [número] de los Nefitas"; "y él de su familia" = "y el [corazón] de su familia") o ante el relativo "que" ("en él que" = "en el que", "él que busque, halla" = "el que busque, halla", aposición "José, él que fué llevado"). Según la RAE (tilde diacrítica: "él" pronombre personal tónico / "el" artículo átono), en todas estas posiciones corresponde "el" SIN tilde; la forma con tilde leída literalmente significa "él" (he/him), lo que rompe la gramática. Clasificación del editor (2026-09-23): "gringismo" -- error de un hablante de español como segunda lengua (probable calco de "he that..." / "that of..." del inglés), no una variante de época: no se halló ninguna fuente normativa ni histórica que lo avale, y la ortografía académica del siglo XIX ya distinguía "él"/"el". Alcance: 156 apariciones en el cuerpo de librodm.txt (ninguna en los bloques de notas), frente a 0 apariciones del artículo sin tilde en estas mismas construcciones ("el de " 0x; "en el que" 0x; los únicos "el que" sin tilde son del tipo nominalizador "el que + subjuntivo", p.ej. "me aflige el que se levanten", construcción distinta). Excluidas deliberadamente ~29 apariciones de "él" que SÍ son pronombre personal correcto ("hizo él que", "sabía él que", "mandóles él que", "deseando de él que", "contra él de la manera", "trataba él de destruir", etc.). Verificación: las 156 confirmadas independientemente contra el texto OCR de Google del PDF de 1920 (google_text_1920/), que lee "él" en todas; imágenes cotejadas a zoom en Alma 43:21 (pages_1920/page_0387.png) y Alma 62:6 (page_0449.png). 1886: el texto OCR del PDF de 1886 (localizado por página vía chapter_map.csv) lee "el" sin tilde en ~141 de las 156 posiciones; ~5 las lee con tilde (1 Nefi 7:5, Mosíah 18:27, III Nefi 4:17, III Nefi 29:7, Mormón 9:17 -- sin verificar contra imagen) y el resto quedan indeterminadas (redacción distinta u OCR ilegible). Conteo global en 1886: "en el que" 22x vs "en él que" 1x; "mayor que el de" 4x vs 0x. Imagen de 1886 cotejada en Alma 40:6 y 40:9 (pages_1886/page_0371.png: "y el de la resurreccion" en ambos -- corrige la entrada suelta anterior de Alma 40:6, que decía "él de en 1886"), Alma 43:21 (page_0380.png, "el de los Nefitas") y Alma 62:6 (page_0442.png, "el de los partidarios"). Conclusión: la forma con tilde es, en esencia, EXCLUSIVA DE 1920; 1886 usa el artículo correcto. Edición moderna en español (churchofjesuschrist.org, cotejada 2026-09-23): Alma 43:21 "mucho mayor que el de los nefitas"; Alma 40:6 "y el de la resurrección"; Éter 12:38 y Alma 62:6 reformulados sin la construcción. Subgrupo dudoso (anotado, no exclui
A25: 24 | B25: 1 Nefi | C25: 1 | D25: 12 | E25: 2 | F25: texto | H25: el Espíritu de Señor | I25: el Espíritu del Señor | J25: letra(s) | K25: 1886 en este lugar exacto | M25: -> _cleaned: corregir a "del Señor" | O25: 30 | U25: 1 Nefi 1:12 el Espíritu de Señor (el Espíritu del Señor) (1920 imprime "él se llenó del Espíritu de Señor," -- falta la "l" de "del" antes de "Señor" --, página 2; confirmado a zoom en alta resolución (pages_1920/page_0024.png); 1886 en este lugar exacto (pages_1886/page_0020.png, book page 2/file 20) imprime IGUALMENTE "él se llenó del Espíritu\nde Señor," -- ERROR COMPARTIDO CON 1886, heredado; la edición moderna del Libro de Mormón en español (churchofjesuschrist.org, 1 Nefi 1:12) trae "lleno del Espíritu del Señor" completo; -> _cleaned: corregir a "del Señor"; preservado como se imprime en librodm_transcribed; hallado 2026-09-12 durante el cotejo manual de imagen del `manual-proofread`, primera unidad tras el frontispicio -- véase `workspace/proofread-1920.md`)
A26: 25 | B26: 1 Nefi | C26: 1 | D26: 15 | E26: 2 | F26: texto | H26: por las cosas el Señor le había mostrado | I26: por las cosas que el Señor le había mostrado | J26: palabra(s)/gramática | K26: o simplemente salta de "cosas" a "el Señor"; 1886 en este lugar exacto | O26: 31 | U26: 1 Nefi 1:15 por las cosas el Señor le había mostrado (por las cosas que el Señor le había mostrado) (1920 omite la palabra "que" en "por las cosas que él había visto, sí, por las cosas el Señor le había mostrado", pág. 2; confirmado a zoom en alta resolución (pages_1920/page_0024.png) -- no hay hueco ni mota de tinta, el texto simplemente salta de "cosas" a "el Señor"; 1886 en este lugar exacto (pages_1886/page_0020.png, book page 2/file 20) SÍ trae el "que" completo, "por las cosas que el Señor le había mostrado" -- construcción paralela con la cláusula anterior ("las cosas que él había visto"); la edición moderna del Libro de Mormón en español (churchofjesuschrist.org, 1 Nefi 1:15) también usa "que"; ERROR EXCLUSIVO DE 1920 -- 1886 no comparte la omisión; hallado mediante cotejo con la capa de OCR incrustada del propio PDF de 1920 [`google_text_1920`/`check_google_crosscheck.py`], 2026-09-10, primer resultado del muestreo piloto de páginas 1-436 -- véase `workspace/diff1920ocr-trans.md`; preservado como se imprime en librodm_transcribed [la transcripción anterior incluía por error el "que" tomado de 1886; corregida silenciosamente para igualar el 1920 real])
A27: 26 | B27: 1 Nefi | C27: 1 | D27: 16 | E27: 2 | F27: texto | H27: hablo á sus hijos | I27: habló á sus hijos | J27: tilde | K27: 1886 en este lugar exacto | O27: 32 | U27: 1 Nefi 1:16 hablo á sus hijos (habló á sus hijos) (1920 imprime "que profetizó y hablo á sus hijos" sin tilde en "hablo" -- rompe el paralelismo con "profetizó", tiempo pasado --, página 2; confirmado a zoom en alta resolución (pages_1920/page_0024.png) y de forma independiente por la capa de OCR incrustada del propio PDF (`google_text_1920/page_0024.txt` line 43, lee igualmente "hablo" sin tilde); 1886 en este lugar exacto (pages_1886/page_0021.png, book page 3/file 21) SÍ trae la tilde, "que profetizó y habló á sus hijos" -- ERROR EXCLUSIVO DE 1920, 1886 no lo comparte; la edición moderna del Libro de Mormón en español también usa "habló"; preservado como se imprime en librodm_transcribed [la transcripción anterior traía por error "habló" con tilde, tomada aparentemente de 1886/corrección tácita; corregida silenciosamente para igualar el 1920 real]; hallado 2026-09-12 durante el cotejo manual de imagen del `manual-proofread` -- este caso concreto había sido descartado antes como ruido de OCR bajo la categoría "Google drops or garbles a single... accent" del `ocr-diff-pilot` sin comprobar la imagen; aquí Google tenía razón -- véase `workspace/proofread-1920.md`)
A28: 27 | B28: 1 Nefi | C28: 1 | D28: 20 | E28: 3 | F28: texto | H28: quiénes | I28: quienes | J28: familia | K28: . USO DE ÉPOCA COMPROBADO: 1886 | L28: relativos "quién/quiénes" y "dónde" con tilde | M28: en librodm_cleaned, suprimir la tilde en las 289 (y conservarla en las 14 excluidas | O28: 87 | U28: FAMILIA relativos "quién/quiénes" y "dónde" con tilde (tilde diacrítica de interrogativo puesta sobre el RELATIVO) -- ENTRADA MAESTRA (2026-09-24, abierta durante el `manual-proofread` de Alma 52, a partir de Alma 52:12 "con quiénes marchó" y 52:27 "ciudad de Abundancia, dónde se encontraton"). NORMA DE ÉPOCA: el Prontuario de ortografía de la lengua castellana de la RAE (1844, oficial para las escuelas por Real Orden) prescribe la tilde en "que, como, cuando, quien, cual, donde y cuanto" solo "siempre que den principio a una cláusula de interrogación o de admiración", y además, sin signos de interrogación, "en los casos en que, para dar la debida entonación a la frase, sea preciso detenerse algo más que de ordinario" en la sílaba (1844: 26-27, citado en M. Peñalver Castillo, Anuario de Letras III-2, 2015) -- es decir, en las interrogativas indirectas tónicas ("no sé quién vino"), NUNCA en el relativo átono ("el hombre á quien vi"); la Gramática de 1870 mantiene la distinción; la norma actual (RAE, Ortografía 2010; DPD s.v. "quién") es la misma. Con "haber/tener": con infinitivo es interrogativo y lleva tilde ("no tenía á quién dejar el reino"); con verbo conjugado es relativo y no la lleva ("no hay quien pueda interpretar"). USO DE ÉPOCA COMPROBADO: 1886 (OCR del PDF completo) escribe el relativo SIEMPRE sin tilde -- fuera de preguntas: 355 "quien/quienes" sin tilde, 146 "donde" sin tilde, 0 "dónde" con tilde, y solo 2 "Quién" con tilde que resultan ser preguntas a las que les falta el "¿" inicial; dentro de preguntas lee 45 "quién" y 9 "dónde" con tilde, prueba de que el OCR sí capta las tildes. La Reina-Valera 1909 (NT, ortografía de época: "á", "fué") sigue la norma de 1844 al pie de la letra: relativos sin tilde ("á quien vosotros no conocéis", "Sobre quien vieres descender") y tilde solo en interrogativas indirectas ("dudando de quién decía", "no sabemos dónde le han puesto"). (El corpus del Quijote de workspace/reference_corpora/ NO sirve como prueba de época: es edición con ortografía moderna -- "fue", "vio", sin "á".) COTEJO POSICIÓN POR POSICIÓN CON 1886 (2026-09-24): (a) automático -- de las 281 posiciones, 276 localizadas en el OCR de 1886 por su contexto, TODAS sin tilde (0 con tilde; 5 no localizadas por ruido del OCR); (b) comprobación visual en las imágenes de 1886 (muestra pedida por el editor), 11 lugares fuera de pregunta, TODOS sin tilde: 1 Nefi 4:26 "á quien yo había matado" (file 28), 1 Nefi 10:8 "á quien no conocéis, quien es más poderoso... de quien no soy digno" (37), 1 Nefi 19:10 "á quienes sacó" (67), Mosíah 7:9 "quien era hijo de Zeniff, quien fué hecho rey" (193), Mosíah 26:21 "Y quien oyere mi voz" (239), Alma 13:15 "á quien Abraham pagaba" (291), Alma 29:5 "quien no conoce... quien distingue" (337), Alma 52:12 "con quienes marchó" (410), Helamán 6:30 "él es quien dirige... él es quien trasmite" (467), Éther 9:14 "á quien llamó Émer" (610), Alma 56:15 "donde encontré" (422), III Nefi 27:11 "de donde no se vuelve" (55
A29: 28 | B29: 1 Nefi | C29: 2 | D29: 2 | E29: 3 | F29: texto | H29: aún | I29: aun | J29: familia | K29: por el mismo camino en que vinieron", donde 1886 lee "aun atrás" | L29: "aún" con tilde por "aun" | M29: en librodm_cleaned, "aun" en (a | O29: 90 | P29: corregido | U29: FAMILIA "aún" con tilde por "aun" (= "hasta, incluso, también, siquiera") -- ENTRADA MAESTRA (2026-09-26, abierta durante el `manual-proofread` de Alma 58, a partir de Alma 58:24 "sí, aún atrás por el mismo camino en que vinieron", donde 1886 lee "aun atrás"). NORMA DE ÉPOCA: desde la Gramática de la RAE de 1880 y hasta 1952 la tilde de "aun" se regía por la POSICIÓN: antepuesto a lo que modifica era monosílabo átono y se escribía "aun"; pospuesto era bisílabo tónico y se escribía "aún" (Á. Calderón Rivera, Thesaurus XLVIII, 1993). Las Nuevas normas de prosodia y ortografía de 1952 (regla 17; texto en BRAE XXXVIII, cuad. CLV, pp. 331-347) adoptaron el criterio de SIGNIFICADO que mantiene la RAE actual (Ortografía 2010): "aún" cuando puede sustituirse por "todavía" ("aún está enfermo; está enfermo aún"); "aun" con el sentido de "hasta, también, inclusive (o siquiera, con negación)" ("aun los sordos han de oírme; ni hizo nada por él ni aun lo intentó"). CRITERIO DE ESTA ENTRADA: sólo se registran los casos que AMBAS normas condenan: (a) "aún" con tilde con el sentido de "hasta/incluso/siquiera" y ANTEPUESTO a lo que modifica ("aún hasta la muerte", "aún como", "sí, aún la ley de Moisés", "ni aún entre los Nefitas", "aún cuando" concesivo, "aún así"); (b) "aun" sin tilde con el sentido de "todavía" y POSPUESTO a lo que modifica. EXCLUIDOS, no registrados: los correctos por ambas normas ("aun" = "incluso" antepuesto; "aún" = "todavía" pospuesto: "viven aún", "no ha llegado aún", "os llama aún", "permanecían aún duros"); los que una norma aprueba y la otra condena ("aun/aún" = "todavía" antepuesto: "aun no se ha concluido mi obra", "aun están vivas", "mas aun quedará"); y las construcciones con "más/mayor" ("aun más", "aún más ruin", "aun mayor"), que admiten las dos lecturas. Clasificación hecha a mano sobre las 389 apariciones de "aun/aún" en el cuerpo de librodm.txt (217 "aún", 172 "aun"), con apoyo en el inglés en las dudosas ("even" frente a "yet/still"). USO DE 1886: el OCR del PDF completo tiene 194 "aun/Aun" y un solo "aún" (Alma 20:30 "aún más dura", caso excluido); de las 194 posiciones de esta entrada en el cuerpo, 179 se localizaron automáticamente en 1886 por su contexto, TODAS "aun" sin tilde, y las 15 restantes (no localizadas por ruido del OCR o redacción distinta) tampoco pueden llevarla, pues el único "aún" de 1886 está en Alma 20:30 -> el grupo (a) es EXCLUSIVO DE 1920; el grupo (b) es COMPARTIDO CON 1886. APARICIONES: (a) "aún" por "aun" -- 192 en el cuerpo: 1 Nefi 2:2; 1 Nefi 5:13; 1 Nefi 12:11; 1 Nefi 12:18; 1 Nefi 13:29; 1 Nefi 17:4; 1 Nefi 17:48; 1 Nefi 17:52; 1 Nefi 20:5; 1 Nefi 22:17 x2; 2 Nefi 1:13; 2 Nefi 1:29; 2 Nefi 2:15; 2 Nefi 2:18; 2 Nefi 3:20 x2; 2 Nefi 4:10; 2 Nefi 4:25; 2 Nefi 5:25; 2 Nefi 9:2; 2 Nefi 9:14; 2 Nefi 9:46; 2 Nefi 13:9; 2 Nefi 18:7; 2 Nefi 19:7; 2 Nefi 19:9; 2 Nefi 23:12; 2 Nefi 24:9; 2 Nefi 25:16; 2 Nefi 26:15; 2 Nefi 26:16; 2 Nefi 27:1; 2 Nefi 27:11; 2 Nefi 28:23; 2 Nefi 28:30; 2 Nefi 29:7; 2 Nefi 31:
A30: 29 | B30: 1 Nefi | C30: 2 | D30: 19 | E30: 5 | F30: texto | H30: con humilidad | I30: con humildad | J30: letra(s) | K30: humildad en versión de 1886 | O30: 33 | U30: 1 Nefi 2:19 con humilidad (con humildad)(humildad en versión de 1886)
A31: 30 | B31: 1 Nefi | C31: 3 | D31: 5 | E31: 5 | F31: texto | H31: quién | I31: quien | J31: familia | K31: . USO DE ÉPOCA COMPROBADO: 1886 | L31: relativos "quién/quiénes" y "dónde" con tilde | M31: en librodm_cleaned, suprimir la tilde en las 289 (y conservarla en las 14 excluidas | O31: 87 | U31: FAMILIA relativos "quién/quiénes" y "dónde" con tilde (tilde diacrítica de interrogativo puesta sobre el RELATIVO) -- ENTRADA MAESTRA (2026-09-24, abierta durante el `manual-proofread` de Alma 52, a partir de Alma 52:12 "con quiénes marchó" y 52:27 "ciudad de Abundancia, dónde se encontraton"). NORMA DE ÉPOCA: el Prontuario de ortografía de la lengua castellana de la RAE (1844, oficial para las escuelas por Real Orden) prescribe la tilde en "que, como, cuando, quien, cual, donde y cuanto" solo "siempre que den principio a una cláusula de interrogación o de admiración", y además, sin signos de interrogación, "en los casos en que, para dar la debida entonación a la frase, sea preciso detenerse algo más que de ordinario" en la sílaba (1844: 26-27, citado en M. Peñalver Castillo, Anuario de Letras III-2, 2015) -- es decir, en las interrogativas indirectas tónicas ("no sé quién vino"), NUNCA en el relativo átono ("el hombre á quien vi"); la Gramática de 1870 mantiene la distinción; la norma actual (RAE, Ortografía 2010; DPD s.v. "quién") es la misma. Con "haber/tener": con infinitivo es interrogativo y lleva tilde ("no tenía á quién dejar el reino"); con verbo conjugado es relativo y no la lleva ("no hay quien pueda interpretar"). USO DE ÉPOCA COMPROBADO: 1886 (OCR del PDF completo) escribe el relativo SIEMPRE sin tilde -- fuera de preguntas: 355 "quien/quienes" sin tilde, 146 "donde" sin tilde, 0 "dónde" con tilde, y solo 2 "Quién" con tilde que resultan ser preguntas a las que les falta el "¿" inicial; dentro de preguntas lee 45 "quién" y 9 "dónde" con tilde, prueba de que el OCR sí capta las tildes. La Reina-Valera 1909 (NT, ortografía de época: "á", "fué") sigue la norma de 1844 al pie de la letra: relativos sin tilde ("á quien vosotros no conocéis", "Sobre quien vieres descender") y tilde solo en interrogativas indirectas ("dudando de quién decía", "no sabemos dónde le han puesto"). (El corpus del Quijote de workspace/reference_corpora/ NO sirve como prueba de época: es edición con ortografía moderna -- "fue", "vio", sin "á".) COTEJO POSICIÓN POR POSICIÓN CON 1886 (2026-09-24): (a) automático -- de las 281 posiciones, 276 localizadas en el OCR de 1886 por su contexto, TODAS sin tilde (0 con tilde; 5 no localizadas por ruido del OCR); (b) comprobación visual en las imágenes de 1886 (muestra pedida por el editor), 11 lugares fuera de pregunta, TODOS sin tilde: 1 Nefi 4:26 "á quien yo había matado" (file 28), 1 Nefi 10:8 "á quien no conocéis, quien es más poderoso... de quien no soy digno" (37), 1 Nefi 19:10 "á quienes sacó" (67), Mosíah 7:9 "quien era hijo de Zeniff, quien fué hecho rey" (193), Mosíah 26:21 "Y quien oyere mi voz" (239), Alma 13:15 "á quien Abraham pagaba" (291), Alma 29:5 "quien no conoce... quien distingue" (337), Alma 52:12 "con quienes marchó" (410), Helamán 6:30 "él es quien dirige... él es quien trasmite" (467), Éther 9:14 "á quien llamó Émer" (610), Alma 56:15 "donde encontré" (422), III Nefi 27:11 "de donde no se vuelve" (55
A32: 31 | B32: 1 Nefi | C32: 3 | D32: 11 | E32: 6 | F32: texto | H32: quién | I32: quien | J32: familia | K32: . USO DE ÉPOCA COMPROBADO: 1886 | L32: relativos "quién/quiénes" y "dónde" con tilde | M32: en librodm_cleaned, suprimir la tilde en las 289 (y conservarla en las 14 excluidas | O32: 87 | U32: FAMILIA relativos "quién/quiénes" y "dónde" con tilde (tilde diacrítica de interrogativo puesta sobre el RELATIVO) -- ENTRADA MAESTRA (2026-09-24, abierta durante el `manual-proofread` de Alma 52, a partir de Alma 52:12 "con quiénes marchó" y 52:27 "ciudad de Abundancia, dónde se encontraton"). NORMA DE ÉPOCA: el Prontuario de ortografía de la lengua castellana de la RAE (1844, oficial para las escuelas por Real Orden) prescribe la tilde en "que, como, cuando, quien, cual, donde y cuanto" solo "siempre que den principio a una cláusula de interrogación o de admiración", y además, sin signos de interrogación, "en los casos en que, para dar la debida entonación a la frase, sea preciso detenerse algo más que de ordinario" en la sílaba (1844: 26-27, citado en M. Peñalver Castillo, Anuario de Letras III-2, 2015) -- es decir, en las interrogativas indirectas tónicas ("no sé quién vino"), NUNCA en el relativo átono ("el hombre á quien vi"); la Gramática de 1870 mantiene la distinción; la norma actual (RAE, Ortografía 2010; DPD s.v. "quién") es la misma. Con "haber/tener": con infinitivo es interrogativo y lleva tilde ("no tenía á quién dejar el reino"); con verbo conjugado es relativo y no la lleva ("no hay quien pueda interpretar"). USO DE ÉPOCA COMPROBADO: 1886 (OCR del PDF completo) escribe el relativo SIEMPRE sin tilde -- fuera de preguntas: 355 "quien/quienes" sin tilde, 146 "donde" sin tilde, 0 "dónde" con tilde, y solo 2 "Quién" con tilde que resultan ser preguntas a las que les falta el "¿" inicial; dentro de preguntas lee 45 "quién" y 9 "dónde" con tilde, prueba de que el OCR sí capta las tildes. La Reina-Valera 1909 (NT, ortografía de época: "á", "fué") sigue la norma de 1844 al pie de la letra: relativos sin tilde ("á quien vosotros no conocéis", "Sobre quien vieres descender") y tilde solo en interrogativas indirectas ("dudando de quién decía", "no sabemos dónde le han puesto"). (El corpus del Quijote de workspace/reference_corpora/ NO sirve como prueba de época: es edición con ortografía moderna -- "fue", "vio", sin "á".) COTEJO POSICIÓN POR POSICIÓN CON 1886 (2026-09-24): (a) automático -- de las 281 posiciones, 276 localizadas en el OCR de 1886 por su contexto, TODAS sin tilde (0 con tilde; 5 no localizadas por ruido del OCR); (b) comprobación visual en las imágenes de 1886 (muestra pedida por el editor), 11 lugares fuera de pregunta, TODOS sin tilde: 1 Nefi 4:26 "á quien yo había matado" (file 28), 1 Nefi 10:8 "á quien no conocéis, quien es más poderoso... de quien no soy digno" (37), 1 Nefi 19:10 "á quienes sacó" (67), Mosíah 7:9 "quien era hijo de Zeniff, quien fué hecho rey" (193), Mosíah 26:21 "Y quien oyere mi voz" (239), Alma 13:15 "á quien Abraham pagaba" (291), Alma 29:5 "quien no conoce... quien distingue" (337), Alma 52:12 "con quienes marchó" (410), Helamán 6:30 "él es quien dirige... él es quien trasmite" (467), Éther 9:14 "á quien llamó Émer" (610), Alma 56:15 "donde encontré" (422), III Nefi 27:11 "de donde no se vuelve" (55
A33: 32 | B33: 1 Nefi | C33: 4 | D33: 9 | E33: 8 | F33: nota | G33: 20 (4a) | H33: Covenios | I33: Convenios | J33: letra(s) | K33: 1886 no tiene aparato de notas con el cual comparar | O33: 34 | U33: Footnote 1 Nefi 4a, 20 Covenios (Convenios) (1920 imprime "Doctrinas y Covenios 17:1" -- falta la "n" de "Convenios" -- en la nota a del capítulo 4, página 8; confirmado a zoom en alta resolución (pages_1920/page_0030.png); 1886 no tiene aparato de notas con el cual comparar; "Doctrinas y Convenios" (con "n") aparece correctamente unas 40 veces más a lo largo de `librodm_foot.txt`/`librodm.txt`, por lo que esta es una errata aislada, no una grafía de casa; error exclusivo de 1920; preservado como se imprime en librodm_transcribed [tanto Block 1 como Block 2 traían por error "Convenios" ya corregido; corregidos silenciosamente ambos para igualar el 1920 real, "Covenios"]; hallado 2026-09-12 durante el cotejo manual de imagen del `manual-proofread` -- véase `workspace/proofread-1920.md`)
A34: 33 | B34: 1 Nefi | C34: 4 | D34: 17 | E34: 9 | F34: texto | H34: Quién | I34: Quien | J34: familia | K34: . USO DE ÉPOCA COMPROBADO: 1886 | L34: relativos "quién/quiénes" y "dónde" con tilde | M34: en librodm_cleaned, suprimir la tilde en las 289 (y conservarla en las 14 excluidas | O34: 87 | U34: FAMILIA relativos "quién/quiénes" y "dónde" con tilde (tilde diacrítica de interrogativo puesta sobre el RELATIVO) -- ENTRADA MAESTRA (2026-09-24, abierta durante el `manual-proofread` de Alma 52, a partir de Alma 52:12 "con quiénes marchó" y 52:27 "ciudad de Abundancia, dónde se encontraton"). NORMA DE ÉPOCA: el Prontuario de ortografía de la lengua castellana de la RAE (1844, oficial para las escuelas por Real Orden) prescribe la tilde en "que, como, cuando, quien, cual, donde y cuanto" solo "siempre que den principio a una cláusula de interrogación o de admiración", y además, sin signos de interrogación, "en los casos en que, para dar la debida entonación a la frase, sea preciso detenerse algo más que de ordinario" en la sílaba (1844: 26-27, citado en M. Peñalver Castillo, Anuario de Letras III-2, 2015) -- es decir, en las interrogativas indirectas tónicas ("no sé quién vino"), NUNCA en el relativo átono ("el hombre á quien vi"); la Gramática de 1870 mantiene la distinción; la norma actual (RAE, Ortografía 2010; DPD s.v. "quién") es la misma. Con "haber/tener": con infinitivo es interrogativo y lleva tilde ("no tenía á quién dejar el reino"); con verbo conjugado es relativo y no la lleva ("no hay quien pueda interpretar"). USO DE ÉPOCA COMPROBADO: 1886 (OCR del PDF completo) escribe el relativo SIEMPRE sin tilde -- fuera de preguntas: 355 "quien/quienes" sin tilde, 146 "donde" sin tilde, 0 "dónde" con tilde, y solo 2 "Quién" con tilde que resultan ser preguntas a las que les falta el "¿" inicial; dentro de preguntas lee 45 "quién" y 9 "dónde" con tilde, prueba de que el OCR sí capta las tildes. La Reina-Valera 1909 (NT, ortografía de época: "á", "fué") sigue la norma de 1844 al pie de la letra: relativos sin tilde ("á quien vosotros no conocéis", "Sobre quien vieres descender") y tilde solo en interrogativas indirectas ("dudando de quién decía", "no sabemos dónde le han puesto"). (El corpus del Quijote de workspace/reference_corpora/ NO sirve como prueba de época: es edición con ortografía moderna -- "fue", "vio", sin "á".) COTEJO POSICIÓN POR POSICIÓN CON 1886 (2026-09-24): (a) automático -- de las 281 posiciones, 276 localizadas en el OCR de 1886 por su contexto, TODAS sin tilde (0 con tilde; 5 no localizadas por ruido del OCR); (b) comprobación visual en las imágenes de 1886 (muestra pedida por el editor), 11 lugares fuera de pregunta, TODOS sin tilde: 1 Nefi 4:26 "á quien yo había matado" (file 28), 1 Nefi 10:8 "á quien no conocéis, quien es más poderoso... de quien no soy digno" (37), 1 Nefi 19:10 "á quienes sacó" (67), Mosíah 7:9 "quien era hijo de Zeniff, quien fué hecho rey" (193), Mosíah 26:21 "Y quien oyere mi voz" (239), Alma 13:15 "á quien Abraham pagaba" (291), Alma 29:5 "quien no conoce... quien distingue" (337), Alma 52:12 "con quienes marchó" (410), Helamán 6:30 "él es quien dirige... él es quien trasmite" (467), Éther 9:14 "á quien llamó Émer" (610), Alma 56:15 "donde encontré" (422), III Nefi 27:11 "de donde no se vuelve" (55
A35: 34 | B35: 1 Nefi | C35: 4 | D35: 26 | E35: 9 | F35: texto | H35: quién | I35: quien | J35: familia | K35: . USO DE ÉPOCA COMPROBADO: 1886 | L35: relativos "quién/quiénes" y "dónde" con tilde | M35: en librodm_cleaned, suprimir la tilde en las 289 (y conservarla en las 14 excluidas | O35: 87 | U35: FAMILIA relativos "quién/quiénes" y "dónde" con tilde (tilde diacrítica de interrogativo puesta sobre el RELATIVO) -- ENTRADA MAESTRA (2026-09-24, abierta durante el `manual-proofread` de Alma 52, a partir de Alma 52:12 "con quiénes marchó" y 52:27 "ciudad de Abundancia, dónde se encontraton"). NORMA DE ÉPOCA: el Prontuario de ortografía de la lengua castellana de la RAE (1844, oficial para las escuelas por Real Orden) prescribe la tilde en "que, como, cuando, quien, cual, donde y cuanto" solo "siempre que den principio a una cláusula de interrogación o de admiración", y además, sin signos de interrogación, "en los casos en que, para dar la debida entonación a la frase, sea preciso detenerse algo más que de ordinario" en la sílaba (1844: 26-27, citado en M. Peñalver Castillo, Anuario de Letras III-2, 2015) -- es decir, en las interrogativas indirectas tónicas ("no sé quién vino"), NUNCA en el relativo átono ("el hombre á quien vi"); la Gramática de 1870 mantiene la distinción; la norma actual (RAE, Ortografía 2010; DPD s.v. "quién") es la misma. Con "haber/tener": con infinitivo es interrogativo y lleva tilde ("no tenía á quién dejar el reino"); con verbo conjugado es relativo y no la lleva ("no hay quien pueda interpretar"). USO DE ÉPOCA COMPROBADO: 1886 (OCR del PDF completo) escribe el relativo SIEMPRE sin tilde -- fuera de preguntas: 355 "quien/quienes" sin tilde, 146 "donde" sin tilde, 0 "dónde" con tilde, y solo 2 "Quién" con tilde que resultan ser preguntas a las que les falta el "¿" inicial; dentro de preguntas lee 45 "quién" y 9 "dónde" con tilde, prueba de que el OCR sí capta las tildes. La Reina-Valera 1909 (NT, ortografía de época: "á", "fué") sigue la norma de 1844 al pie de la letra: relativos sin tilde ("á quien vosotros no conocéis", "Sobre quien vieres descender") y tilde solo en interrogativas indirectas ("dudando de quién decía", "no sabemos dónde le han puesto"). (El corpus del Quijote de workspace/reference_corpora/ NO sirve como prueba de época: es edición con ortografía moderna -- "fue", "vio", sin "á".) COTEJO POSICIÓN POR POSICIÓN CON 1886 (2026-09-24): (a) automático -- de las 281 posiciones, 276 localizadas en el OCR de 1886 por su contexto, TODAS sin tilde (0 con tilde; 5 no localizadas por ruido del OCR); (b) comprobación visual en las imágenes de 1886 (muestra pedida por el editor), 11 lugares fuera de pregunta, TODOS sin tilde: 1 Nefi 4:26 "á quien yo había matado" (file 28), 1 Nefi 10:8 "á quien no conocéis, quien es más poderoso... de quien no soy digno" (37), 1 Nefi 19:10 "á quienes sacó" (67), Mosíah 7:9 "quien era hijo de Zeniff, quien fué hecho rey" (193), Mosíah 26:21 "Y quien oyere mi voz" (239), Alma 13:15 "á quien Abraham pagaba" (291), Alma 29:5 "quien no conoce... quien distingue" (337), Alma 52:12 "con quienes marchó" (410), Helamán 6:30 "él es quien dirige... él es quien trasmite" (467), Éther 9:14 "á quien llamó Émer" (610), Alma 56:15 "donde encontré" (422), III Nefi 27:11 "de donde no se vuelve" (55
A36: 35 | B36: 1 Nefi | C36: 4 | D36: 36 | E36: 10 | F36: texto | H36: que nos perseguieran | I36: que nos persiguieran | J36: letra(s) | K36: perseguieran en 1886 | O36: 35 | U36: 1 Nefi 4:36 que nos perseguieran (que nos persiguieran) (perseguieran en 1886)
A37: 36 | B37: 1 Nefi | C37: 5 | D37: 1 | E37: 10 | F37: texto | H37: acausa | I37: a causa | J37: puntuación/espacio | K37: á cáusa en 1886 | O37: 36 | U37: 1 Nefi 5:1 acausa (a causa) (á cáusa en 1886)
A38: 37 | B38: 1 Nefi | C38: 5 | D38: 2 | E38: 10 | F38: texto | H38: quién | I38: quien | J38: familia | K38: . USO DE ÉPOCA COMPROBADO: 1886 | L38: relativos "quién/quiénes" y "dónde" con tilde | M38: en librodm_cleaned, suprimir la tilde en las 289 (y conservarla en las 14 excluidas | O38: 87 | U38: FAMILIA relativos "quién/quiénes" y "dónde" con tilde (tilde diacrítica de interrogativo puesta sobre el RELATIVO) -- ENTRADA MAESTRA (2026-09-24, abierta durante el `manual-proofread` de Alma 52, a partir de Alma 52:12 "con quiénes marchó" y 52:27 "ciudad de Abundancia, dónde se encontraton"). NORMA DE ÉPOCA: el Prontuario de ortografía de la lengua castellana de la RAE (1844, oficial para las escuelas por Real Orden) prescribe la tilde en "que, como, cuando, quien, cual, donde y cuanto" solo "siempre que den principio a una cláusula de interrogación o de admiración", y además, sin signos de interrogación, "en los casos en que, para dar la debida entonación a la frase, sea preciso detenerse algo más que de ordinario" en la sílaba (1844: 26-27, citado en M. Peñalver Castillo, Anuario de Letras III-2, 2015) -- es decir, en las interrogativas indirectas tónicas ("no sé quién vino"), NUNCA en el relativo átono ("el hombre á quien vi"); la Gramática de 1870 mantiene la distinción; la norma actual (RAE, Ortografía 2010; DPD s.v. "quién") es la misma. Con "haber/tener": con infinitivo es interrogativo y lleva tilde ("no tenía á quién dejar el reino"); con verbo conjugado es relativo y no la lleva ("no hay quien pueda interpretar"). USO DE ÉPOCA COMPROBADO: 1886 (OCR del PDF completo) escribe el relativo SIEMPRE sin tilde -- fuera de preguntas: 355 "quien/quienes" sin tilde, 146 "donde" sin tilde, 0 "dónde" con tilde, y solo 2 "Quién" con tilde que resultan ser preguntas a las que les falta el "¿" inicial; dentro de preguntas lee 45 "quién" y 9 "dónde" con tilde, prueba de que el OCR sí capta las tildes. La Reina-Valera 1909 (NT, ortografía de época: "á", "fué") sigue la norma de 1844 al pie de la letra: relativos sin tilde ("á quien vosotros no conocéis", "Sobre quien vieres descender") y tilde solo en interrogativas indirectas ("dudando de quién decía", "no sabemos dónde le han puesto"). (El corpus del Quijote de workspace/reference_corpora/ NO sirve como prueba de época: es edición con ortografía moderna -- "fue", "vio", sin "á".) COTEJO POSICIÓN POR POSICIÓN CON 1886 (2026-09-24): (a) automático -- de las 281 posiciones, 276 localizadas en el OCR de 1886 por su contexto, TODAS sin tilde (0 con tilde; 5 no localizadas por ruido del OCR); (b) comprobación visual en las imágenes de 1886 (muestra pedida por el editor), 11 lugares fuera de pregunta, TODOS sin tilde: 1 Nefi 4:26 "á quien yo había matado" (file 28), 1 Nefi 10:8 "á quien no conocéis, quien es más poderoso... de quien no soy digno" (37), 1 Nefi 19:10 "á quienes sacó" (67), Mosíah 7:9 "quien era hijo de Zeniff, quien fué hecho rey" (193), Mosíah 26:21 "Y quien oyere mi voz" (239), Alma 13:15 "á quien Abraham pagaba" (291), Alma 29:5 "quien no conoce... quien distingue" (337), Alma 52:12 "con quienes marchó" (410), Helamán 6:30 "él es quien dirige... él es quien trasmite" (467), Éther 9:14 "á quien llamó Émer" (610), Alma 56:15 "donde encontré" (422), III Nefi 27:11 "de donde no se vuelve" (55
A39: 38 | B39: 1 Nefi | C39: 5 | D39: 3 | E39: 10 | F39: texto | H39: lenguage | I39: lenguaje | J39: familia | K39: pág. 466/467, LIBRO DE HELAMÁN CAPÍTULO 11; 1886 comparte "pillage" en este lugar exacto, pages_18 | L39: -age | M39: -> _cleaned (DECISIÓN DEL EDITOR | O39: 22 | U39: FAMILIA -age (por -aje) -- grafía "-age" arcaica donde el español moderno escribe "-aje". ENTRADA MAESTRA (2026-09-09; consolida las entradas antes dispersas de 1 Nefi 1:2 y 1 Nefi 5:3, ambas "el/este lenguage"). Alcance: "lenguage" 11 apariciones en el cuerpo (`grep -nE "lenguage" librodm_transcribed.txt`) + "lenguage del libro" en el índice (pág. xiii) + "344 días de pasage" en el índice (pág. xiii, entrada de Éther 6:11) + "pillage" 1x en el cuerpo (Helamán 11:25, "Y entregándose al pillage y al asesinato", pág. 466/467, LIBRO DE HELAMÁN CAPÍTULO 11; 1886 comparte "pillage" en este lugar exacto, pages_1886/page_0481.png, book page 463/file 481). Frente a "lenguaje" 3x, "pasaje" 12x y "pillaje/pillajes" 13x en el cuerpo (Helamán 11:25 es la ÚNICA aparición de "pillage" -- 1920 usa "pillaje" en las otras 13). La grafía "-age" (mensage/linage/viage/salvage/lenguage/pasage) fue la NORMA del español hasta que la RAE estandarizó "-aje" (~1815); para 1886/1920 era arcaica pero aún frecuente en imprenta. 1920 ya ha completado el cambio a "-aje" en TODAS las demás palabras (mensaje 22x, viaje 29x, salvaje 5x, linaje 4x, ultraje 2x -- 0 con "-age"), quedando SOLO "lenguage" (su forma de casa dominante, 11:3) y un "pasage" suelto en el índice. 1886: comparte "lenguage" ("lenguage en 1886" en las entradas originales de 1 Nefi 1:2 y 5:3). Atestiguación externa: "-age" en estas palabras = 0 en Quijote / Reina-Valera 1909 NT / Reina-Valera Biblia completa; "lenguaje" Quijote 10, "pasaje" Quijote 10, "pillaje" 1 en Reina-Valera Biblia completa (0 "pillage"). CLASIFICACIÓN: grafía ortográfica arcaica de época (norma pre-1815), compartida con 1886, NO un error tipográfico; edición inconsistente (casi todo "-aje", pero "lenguage" mayoritario). -> _cleaned (DECISIÓN DEL EDITOR): normalizar las apariciones restantes de "-age" a "-aje" (lenguage -> lenguaje; pasage -> pasaje; pillage -> pillaje, forma ya mayoritaria 13:1 en la propia 1920), como regularización de una grafía de época, no como corrección de errores. Preservado como se imprime en librodm_transcribed.
A40: 39 | B40: 1 Nefi | C40: 5 | D40: 4 | E40: 10 | F40: texto | H40: y hubieria permanecido | I40: y hubiera permanecido | J40: letra(s) | K40: 1886 en este lugar exacto | O40: 37 | U40: 1 Nefi 5:4 y hubieria permanecido (y hubiera permanecido) (1920 imprime "no habría conocido su bondad y hubieria permanecido en Jerusalem", página 10/11 [línea de vuelta de página]; confirmado a zoom en alta resolución (pages_1920/page_0032.png fin + pages_1920/page_0033.png inicio); único "hubieria" en todo el documento (`grep -c hubieria librodm_transcribed.txt` = 1); 1886 en este lugar exacto (pages_1886/page_0029.png, book page 11/file 29) trae "hubiera permanecido" sin la "i" espuria; error exclusivo de 1920; preservado como se imprime en librodm_transcribed; entrada corregida 2026-09-12 durante el `manual-proofread` -- el fragmento citado originalmente, "no hubieria visto", no corresponde a ningún texto real de este versículo [ese tramo dice correctamente "si no hubiere visto" / "no habría conocido"]; la palabra "hubieria" realmente aparece más adelante en el mismo v.4, "y hubieria permanecido"; véase `workspace/proofread-1920.md`)
A41: 40 | B41: 1 Nefi | C41: 5 | D41: 13 | E41: 11 | F41: texto | H41: aún | I41: aun | J41: familia | K41: por el mismo camino en que vinieron", donde 1886 lee "aun atrás" | L41: "aún" con tilde por "aun" | M41: en librodm_cleaned, "aun" en (a | O41: 90 | U41: FAMILIA "aún" con tilde por "aun" (= "hasta, incluso, también, siquiera") -- ENTRADA MAESTRA (2026-09-26, abierta durante el `manual-proofread` de Alma 58, a partir de Alma 58:24 "sí, aún atrás por el mismo camino en que vinieron", donde 1886 lee "aun atrás"). NORMA DE ÉPOCA: desde la Gramática de la RAE de 1880 y hasta 1952 la tilde de "aun" se regía por la POSICIÓN: antepuesto a lo que modifica era monosílabo átono y se escribía "aun"; pospuesto era bisílabo tónico y se escribía "aún" (Á. Calderón Rivera, Thesaurus XLVIII, 1993). Las Nuevas normas de prosodia y ortografía de 1952 (regla 17; texto en BRAE XXXVIII, cuad. CLV, pp. 331-347) adoptaron el criterio de SIGNIFICADO que mantiene la RAE actual (Ortografía 2010): "aún" cuando puede sustituirse por "todavía" ("aún está enfermo; está enfermo aún"); "aun" con el sentido de "hasta, también, inclusive (o siquiera, con negación)" ("aun los sordos han de oírme; ni hizo nada por él ni aun lo intentó"). CRITERIO DE ESTA ENTRADA: sólo se registran los casos que AMBAS normas condenan: (a) "aún" con tilde con el sentido de "hasta/incluso/siquiera" y ANTEPUESTO a lo que modifica ("aún hasta la muerte", "aún como", "sí, aún la ley de Moisés", "ni aún entre los Nefitas", "aún cuando" concesivo, "aún así"); (b) "aun" sin tilde con el sentido de "todavía" y POSPUESTO a lo que modifica. EXCLUIDOS, no registrados: los correctos por ambas normas ("aun" = "incluso" antepuesto; "aún" = "todavía" pospuesto: "viven aún", "no ha llegado aún", "os llama aún", "permanecían aún duros"); los que una norma aprueba y la otra condena ("aun/aún" = "todavía" antepuesto: "aun no se ha concluido mi obra", "aun están vivas", "mas aun quedará"); y las construcciones con "más/mayor" ("aun más", "aún más ruin", "aun mayor"), que admiten las dos lecturas. Clasificación hecha a mano sobre las 389 apariciones de "aun/aún" en el cuerpo de librodm.txt (217 "aún", 172 "aun"), con apoyo en el inglés en las dudosas ("even" frente a "yet/still"). USO DE 1886: el OCR del PDF completo tiene 194 "aun/Aun" y un solo "aún" (Alma 20:30 "aún más dura", caso excluido); de las 194 posiciones de esta entrada en el cuerpo, 179 se localizaron automáticamente en 1886 por su contexto, TODAS "aun" sin tilde, y las 15 restantes (no localizadas por ruido del OCR o redacción distinta) tampoco pueden llevarla, pues el único "aún" de 1886 está en Alma 20:30 -> el grupo (a) es EXCLUSIVO DE 1920; el grupo (b) es COMPARTIDO CON 1886. APARICIONES: (a) "aún" por "aun" -- 192 en el cuerpo: 1 Nefi 2:2; 1 Nefi 5:13; 1 Nefi 12:11; 1 Nefi 12:18; 1 Nefi 13:29; 1 Nefi 17:4; 1 Nefi 17:48; 1 Nefi 17:52; 1 Nefi 20:5; 1 Nefi 22:17 x2; 2 Nefi 1:13; 2 Nefi 1:29; 2 Nefi 2:15; 2 Nefi 2:18; 2 Nefi 3:20 x2; 2 Nefi 4:10; 2 Nefi 4:25; 2 Nefi 5:25; 2 Nefi 9:2; 2 Nefi 9:14; 2 Nefi 9:46; 2 Nefi 13:9; 2 Nefi 18:7; 2 Nefi 19:7; 2 Nefi 19:9; 2 Nefi 23:12; 2 Nefi 24:9; 2 Nefi 25:16; 2 Nefi 26:15; 2 Nefi 26:16; 2 Nefi 27:1; 2 Nefi 27:11; 2 Nefi 28:23; 2 Nefi 28:30; 2 Nefi 29:7; 2 Nefi 31:
...

Sheet Familias
A1: Línea en el registro | B1: Familia | C1: Filas en "Errores" | D1: 1946 – versículos a mirar | E1: 1946 – resultado | F1: 1946 – nota | G1: Decisión Gutenberg (toda la familia) | H1: Decisión moderna (toda la familia) | I1: Comentarios | J1: Entrada completa
A2: 22 | B2: -age | C2: =COUNTIF(Errores!L:L,B2) | D2: 1 Nefi 1:2; 1 Nefi 5:3; Helamán 11:25 | E2: corrige todos | F2: lenguaje, pillaje | J2: FAMILIA -age (por -aje) -- grafía "-age" arcaica donde el español moderno escribe "-aje". ENTRADA MAESTRA (2026-09-09; consolida las entradas antes dispersas de 1 Nefi 1:2 y 1 Nefi 5:3, ambas "el/este lenguage"). Alcance: "lenguage" 11 apariciones en el cuerpo (`grep -nE "lenguage" librodm_transcribed.txt`) + "lenguage del libro" en el índice (pág. xiii) + "344 días de pasage" en el índice (pág. xiii, entrada de Éther 6:11) + "pillage" 1x en el cuerpo (Helamán 11:25, "Y entregándose al pillage y al asesinato", pág. 466/467, LIBRO DE HELAMÁN CAPÍTULO 11; 1886 comparte "pillage" en este lugar exacto, pages_1886/page_0481.png, book page 463/file 481). Frente a "lenguaje" 3x, "pasaje" 12x y "pillaje/pillajes" 13x en el cuerpo (Helamán 11:25 es la ÚNICA aparición de "pillage" -- 1920 usa "pillaje" en las otras 13). La grafía "-age" (mensage/linage/viage/salvage/lenguage/pasage) fue la NORMA del español hasta que la RAE estandarizó "-aje" (~1815); para 1886/1920 era arcaica pero aún frecuente en imprenta. 1920 ya ha completado el cambio a "-aje" en TODAS las demás palabras (mensaje 22x, viaje 29x, salvaje 5x, linaje 4x, ultraje 2x -- 0 con "-age"), quedando SOLO "lenguage" (su forma de casa dominante, 11:3) y un "pasage" suelto en el índice. 1886: comparte "lenguage" ("lenguage en 1886" en las entradas originales de 1 Nefi 1:2 y 5:3). Atestiguación externa: "-age" en estas palabras = 0 en Quijote / Reina-Valera 1909 NT / Reina-Valera Biblia completa; "lenguaje" Quijote 10, "pasaje" Quijote 10, "pillaje" 1 en Reina-Valera Biblia completa (0 "pillage"). CLASIFICACIÓN: grafía ortográfica arcaica de época (norma pre-1815), compartida con 1886, NO un error tipográfico; edición inconsistente (casi todo "-aje", pero "lenguage" mayoritario). -> _cleaned (DECISIÓN DEL EDITOR): normalizar las apariciones restantes de "-age" a "-aje" (lenguage -> lenguaje; pasage -> pasaje; pillage -> pillaje, forma ya mayoritaria 13:1 en la propia 1920), como regularización de una grafía de época, no como corrección de errores. Preservado como se imprime en librodm_transcribed.
A3: 23 | B3: Mosíah/Mosiah | C3: =COUNTIF(Errores!L:L,B3) | D3: Omni 1:18; Alma 1:1; Mosíah nota 1328 (17a); Mosíah nota 1563 (27x); Alma nota 2890 (50-2c) | E3: corrige todos | J3: FAMILIA Mosíah/Mosiah (acento inconsistente) -- el nombre del libro/rey "Mosíah" se imprime en 1920 unas veces con tilde esdrújula y otras sin ella, en ambos bloques de la transcripción. ENTRADA MAESTRA (2026-09-13, abierta durante el `manual-proofread` de 1 Nefi 11 tras encontrar que la nota 11d/70 citaba "Mosíah 15:2-5" con tilde en la transcripción cuando la imagen de 1920 (pages_1920/page_0043.png) imprime "Mosiah" sin tilde -- corregido ese caso puntual para igualar la imagen). Alcance (conteo bruto original de 2026-09-13, SUPERADO -- véase el RECUENTO VERIFICADO de 2026-10-16 al final de esta entrada): `librodm_foot.txt` 507 "Mosíah" con tilde / 115 "Mosiah" sin tilde; `librodm.txt` (cuerpo + Block 2) 348 con tilde / 54 sin tilde -- en ambos archivos la forma CON tilde es mayoritaria (~82-86%), pero la minoría sin tilde es demasiado numerosa para tratarse de simples deslices aislados; probablemente refleja la propia inconsistencia del taller de imprenta de 1920, no un patrón limpio. Comprobación de destino moderno (2026-09-13, churchofjesuschrist.org, título y encabezado del Libro de Mosíah): la edición actual en español escribe "Mosíah" CON tilde de forma uniforme. CLASIFICACIÓN: inconsistencia ortográfica de imprenta de 1920, no un error puntual de la transcripción salvo caso por caso (como 11d/70 arriba, donde la transcripción no igualaba la imagen real). DECISIÓN DEL EDITOR (2026-09-13): la transcripción corriente sigue leyendo cada aparición tal como se verifique contra su propia imagen durante el cotejo manual (no se asume la forma mayoritaria); en la futura versión `_cleaned`, normalizar TODAS las apariciones a "Mosíah" con tilde, igualando la ortografía moderna. Pendiente: una auditoría dedicada, imagen por imagen, de las apariciones sin tilde restantes no se ha emprendido todavía (fuera del alcance de un solo capítulo) -- véase `workspace/proofread-1920.md`, sección "1 Nefi 11", para más detalle. CORRECCIÓN (2026-10-11, barrido de tildes en notas): el caso que abrió esta entrada, la nota 11d/70 de 1 Nefi ("Mosíah 15:2-5", pages_1920/page_0043.png), SÍ lleva tilde en la impresión -- el editor la vio con claridad en un recorte a tamaño moderado; la lectura "sin tilde" de 2026-09-13 era un error de zoom sobre tinta cargada. La transcripción vuelve a "Mosíah" en ambos bloques. Corregidas también 2 Nefi 2e/264 y 9g/364 ("Mosiah" -> "Mosíah"). RECUENTO VERIFICADO (2026-10-16; cada aparición cotejada contra la imagen el 2026-10-11/12 en el barrido de tildes en notas: hojas de contacto a 4x de todos los Mosíah/Mosiah de las notas, y el 2026-10-12 un recorte individual de cada "Mosiah" sin tilde restante, notas y cuerpo): `librodm_foot.txt` (Block 1) 609 "Mosíah" / 14 "Mosiah"; cuerpo de `librodm.txt` (incluidos encabezados y sumarios en cursiva) 82 / 2; Block 2 310 / 4 (las demás notas "Véase x, Mosiah N" se resuelven a un número en Block 2). Las 14 notas sin tilde (punto redondo en la impresión): Mosíah 12e (1251), 16a (1311), 16q (1327), 17a (1328), 18h (1343), 18l (1347), 18w (1358), 19i (1367), 19s (1377), 24h (1481), 27x (1563); Alma 36j (2537), 42y (2667), 50-2c (2890). Las 2 del cuerpo: Omni 1:18 "idioma de Mosiah, Zarahemla" (pág. 158) y Alma 1:1 "Mosiah, quién pugnó" (pág. 235). El recuento original (115 sin tilde en Block 1) se debía sobre todo a deslices de transcripción: 82 notas imprimen "Mosíah" con tilde clara (tinta cargada que las pasadas anteriores leyeron como punto), corregidas el 2026-10-12; además 1 Nefi 11d, 2 Nefi 2e y 9g, Alma 12-2m y 22-2n, III Nefi 11n y el sumario en cursiva de Alma 17 (pág. 286). No se cuentan aquí las erratas registradas aparte: "Nosíah" (Mosíah 23l, 1458) y "Mlsíah" (Mosíah 25i, 1504). Resultado: la forma con tilde es el 97,8 % en las notas (609 de 623) y el 97,6 % en el cuerpo (82 de 84). Detalle: workspace/proofread-1920.md, sección "Footnote accent-variant sweep".
